{"uuid": "a763b217-4b86-43c6-98fb-3455f38bb0a4", "children": ["65bdeae5-2b6f-46f9-92ce-b137f96b5e5d"], "befores": [{"name": "log_on_failure", "status": "passed", "start": 1721330688238, "stop": 1721330688238}], "afters": [{"name": "log_on_failure::0", "status": "broken", "statusDetails": {"message": "AttributeError: 'Function' object has no attribute 'rep_call'\n", "trace": "  File \"C:\\Users\\HP\\AppData\\Local\\Programs\\Python\\Python311\\Lib\\site-packages\\allure_commons\\_allure.py\", line 221, in __call__\n    return self._fixture_function(*args, **kwargs)\n           ^^^^^^^^^^^^^^^^^^^^^^^^^^^^^^^^^^^^^^^\n  File \"C:\\Users\\HP\\AppData\\Local\\Programs\\Python\\Python311\\Lib\\site-packages\\_pytest\\fixtures.py\", line 911, in _teardown_yield_fixture\n    next(it)\n  File \"E:\\WorkSpace\\appium-python-pytest\\TestCases\\conftest.py\", line 45, in log_on_failure\n    if item.rep_call.failed:\n       ^^^^^^^^^^^^^\n"}, "start": 1721330716208, "stop": 1721330716209}], "start": 1721330688238, "stop": 1721330716209}